data/sample_events.csv
timestamp_ns,event_type,order_id,side,price_ticks,quantity,symbol_id,sequence
1000,ADD,1,BUY,10025,10,1,1
1010,ADD,2,SELL,10030,8,1,2
1020,ADD,3,BUY,10020,15,1,3
1030,CANCEL,1,BUY,10025,10,1,4
1040,ADD,4,BUY,10027,12,1,5
1050,EXECUTE,2,SELL,10030,3,1,6
1060,MODIFY,4,BUY,10028,10,1,7
1070,CANCEL,99,SELL,10050,1,1,8
1080,ADD,5,SELL,10028,4,1,9
